output.txt
Order: GTSC SELL 697 993 
----------------------------------------------------------------------------------------------------
Bids:
Asks:
PRICE: 6970
GTSC SELL 6970 993 1788764739276 1

----------------------------------------------------------------------------------------------------
Order: JPMS BUY 600.3 996 
----------------------------------------------------------------------------------------------------
Bids:
PRICE: 6003
JPMS BUY 6003 996 1788764739276 2
Asks:
PRICE: 6970
GTSC SELL 6970 993 1788764739276 1

----------------------------------------------------------------------------------------------------
Order: JPMS BUY 463.2 1000 
----------------------------------------------------------------------------------------------------
Bids:
PRICE: 4632
JPMS BUY 4632 1000 1788764739276 3
PRICE: 6003
JPMS BUY 6003 996 1788764739276 2
Asks:
PRICE: 6970
GTSC SELL 6970 993 1788764739276 1

----------------------------------------------------------------------------------------------------
Order: NITE BUY 351.2 1004 
----------------------------------------------------------------------------------------------------
Bids:
PRICE: 3512
NITE BUY 3512 1004 1788764739276 4
PRICE: 4632
JPMS BUY 4632 1000 1788764739276 3
PRICE: 6003
JPMS BUY 6003 996 1788764739276 2
Asks:
PRICE: 6970
GTSC SELL 6970 993 1788764739276 1

----------------------------------------------------------------------------------------------------
Order: VIRT SELL 433.5 1016 
----------------------------------------------------------------------------------------------------
Bids:
PRICE: 3512
NITE BUY 3512 1004 1788764739276 4
PRICE: 4632
JPMS BUY 4632 980 1788764739276 3
Asks:
PRICE: 6970
GTSC SELL 6970 993 1788764739276 1

----------------------------------------------------------------------------------------------------
Trade:
Resting Order: JPMS BUY 6003 996 1788764739276 2
Agressor Order: VIRT SELL 4335 1016 1788764739276 5
Price: 6003
Volume: 996
Trade:
Resting Order: JPMS BUY 4632 1000 1788764739276 3
Agressor Order: VIRT SELL 4335 20 1788764739276 5
Price: 4632
Volume: 20
Order: JPMS SELL 467.5 1016 
----------------------------------------------------------------------------------------------------
Bids:
PRICE: 3512
NITE BUY 3512 1004 1788764739276 4
PRICE: 4632
JPMS BUY 4632 980 1788764739276 3
Asks:
PRICE: 4675
JPMS SELL 4675 1016 1788764739276 6
PRICE: 6970
GTSC SELL 6970 993 1788764739276 1

----------------------------------------------------------------------------------------------------
Order: VIRT SELL 449.2 1005 
----------------------------------------------------------------------------------------------------
Bids:
PRICE: 3512
NITE BUY 3512 1004 1788764739276 4
Asks:
PRICE: 4492
VIRT SELL 4492 25 1788764739276 7
PRICE: 4675
JPMS SELL 4675 1016 1788764739276 6
PRICE: 6970
GTSC SELL 6970 993 1788764739276 1

----------------------------------------------------------------------------------------------------
Trade:
Resting Order: JPMS BUY 4632 980 1788764739276 3
Agressor Order: VIRT SELL 4492 1005 1788764739276 7
Price: 4632
Volume: 980
Order: GTSC BUY 379.4 1001 
----------------------------------------------------------------------------------------------------
Bids:
PRICE: 3512
NITE BUY 3512 1004 1788764739276 4
PRICE: 3794
GTSC BUY 3794 1001 1788764739276 8
Asks:
PRICE: 4492
VIRT SELL 4492 25 1788764739276 7
PRICE: 4675
JPMS SELL 4675 1016 1788764739276 6
PRICE: 6970
GTSC SELL 6970 993 1788764739276 1

----------------------------------------------------------------------------------------------------
Order: GSCO SELL 333.1 996 
----------------------------------------------------------------------------------------------------
Bids:
PRICE: 3512
NITE BUY 3512 1004 1788764739276 4
PRICE: 3794
GTSC BUY 3794 5 1788764739276 8
Asks:
PRICE: 4492
VIRT SELL 4492 25 1788764739276 7
PRICE: 4675
JPMS SELL 4675 1016 1788764739276 6
PRICE: 6970
GTSC SELL 6970 993 1788764739276 1

----------------------------------------------------------------------------------------------------
Trade:
Resting Order: GTSC BUY 3794 1001 1788764739276 8
Agressor Order: GSCO SELL 3331 996 1788764739276 9
Price: 3794
Volume: 996
Order: JPMS SELL 459 995 
----------------------------------------------------------------------------------------------------
Bids:
PRICE: 3512
NITE BUY 3512 1004 1788764739276 4
PRICE: 3794
GTSC BUY 3794 5 1788764739276 8
Asks:
PRICE: 4492
VIRT SELL 4492 25 1788764739276 7
PRICE: 4590
JPMS SELL 4590 995 1788764739277 10
PRICE: 4675
JPMS SELL 4675 1016 1788764739276 6
PRICE: 6970
GTSC SELL 6970 993 1788764739276 1

----------------------------------------------------------------------------------------------------
Order: GTSC BUY 307.9 997 
----------------------------------------------------------------------------------------------------
Bids:
PRICE: 3079
GTSC BUY 3079 997 1788764739277 11
PRICE: 3512
NITE BUY 3512 1004 1788764739276 4
PRICE: 3794
GTSC BUY 3794 5 1788764739276 8
Asks:
PRICE: 4492
VIRT SELL 4492 25 1788764739276 7
PRICE: 4590
JPMS SELL 4590 995 1788764739277 10
PRICE: 4675
JPMS SELL 4675 1016 1788764739276 6
PRICE: 6970
GTSC SELL 6970 993 1788764739276 1

----------------------------------------------------------------------------------------------------
Order: CDEL BUY 353.2 1002 
----------------------------------------------------------------------------------------------------
Bids:
PRICE: 3079
GTSC BUY 3079 997 1788764739277 11
PRICE: 3512
NITE BUY 3512 1004 1788764739276 4
PRICE: 3532
CDEL BUY 3532 1002 1788764739277 12
PRICE: 3794
GTSC BUY 3794 5 1788764739276 8
Asks:
PRICE: 4492
VIRT SELL 4492 25 1788764739276 7
PRICE: 4590
JPMS SELL 4590 995 1788764739277 10
PRICE: 4675
JPMS SELL 4675 1016 1788764739276 6
PRICE: 6970
GTSC SELL 6970 993 1788764739276 1

----------------------------------------------------------------------------------------------------
Order: JETA SELL 242.7 1006 
----------------------------------------------------------------------------------------------------
Bids:
PRICE: 3079
GTSC BUY 3079 997 1788764739277 11
PRICE: 3512
NITE BUY 3512 1004 1788764739276 4
PRICE: 3532
CDEL BUY 3532 1 1788764739277 12
Asks:
PRICE: 4492
VIRT SELL 4492 25 1788764739276 7
PRICE: 4590
JPMS SELL 4590 995 1788764739277 10
PRICE: 4675
JPMS SELL 4675 1016 1788764739276 6
PRICE: 6970
GTSC SELL 6970 993 1788764739276 1

----------------------------------------------------------------------------------------------------
Trade:
Resting Order: GTSC BUY 3794 5 1788764739276 8
Agressor Order: JETA SELL 2427 1006 1788764739277 13
Price: 3794
Volume: 5
Trade:
Resting Order: CDEL BUY 3532 1002 1788764739277 12
Agressor Order: JETA SELL 2427 1001 1788764739277 13
Price: 3532
Volume: 1001
Order: GSCO SELL 157.9 1021 
----------------------------------------------------------------------------------------------------
Bids:
PRICE: 3079
GTSC BUY 3079 981 1788764739277 11
Asks:
PRICE: 4492
VIRT SELL 4492 25 1788764739276 7
PRICE: 4590
JPMS SELL 4590 995 1788764739277 10
PRICE: 4675
JPMS SELL 4675 1016 1788764739276 6
PRICE: 6970
GTSC SELL 6970 993 1788764739276 1

----------------------------------------------------------------------------------------------------
Trade:
Resting Order: CDEL BUY 3532 1 1788764739277 12
Agressor Order: GSCO SELL 1579 1021 1788764739277 14
Price: 3532
Volume: 1
Trade:
Resting Order: NITE BUY 3512 1004 1788764739276 4
Agressor Order: GSCO SELL 1579 1020 1788764739277 14
Price: 3512
Volume: 1004
Trade:
Resting Order: GTSC BUY 3079 997 1788764739277 11
Agressor Order: GSCO SELL 1579 16 1788764739277 14
Price: 3079
Volume: 16
Order: GTSC SELL 176.7 1016 
----------------------------------------------------------------------------------------------------
Bids:
Asks:
PRICE: 1767
GTSC SELL 1767 35 1788764739277 15
PRICE: 4492
VIRT SELL 4492 25 1788764739276 7
PRICE: 4590
JPMS SELL 4590 995 1788764739277 10
PRICE: 4675
JPMS SELL 4675 1016 1788764739276 6
PRICE: 6970
GTSC SELL 6970 993 1788764739276 1

----------------------------------------------------------------------------------------------------
